<?xml version="1.0" ?>
<!-- =================================================================================== -->
<!-- |    This document was autogenerated by xacro from conveyor_belt.urdf.xacro       | -->
<!-- |    EDITING THIS FILE BY HAND IS NOT RECOMMENDED                                 | -->
<!-- =================================================================================== -->
<robot name="conveyor_belt">
  <link name="world"/>
  <joint name="fixed" type="fixed">
    <parent link="world"/>
    <child link="belt_visual"/>
    <origin rpy="0.0 0.0 0.0" xyz="0.0 0.0 0.0"/>
  </joint>
  <link name="belt_visual">
    <collision>
      <origin rpy="0 0 0" xyz="0.0 0.0 0.0"/>
      <geometry>
        <box size="10.0 0.18 0.4"/>
      </geometry>
    </collision>
    <visual>
      <origin rpy="0 0 0" xyz="0.0 0.0 0.0"/>
      <geometry>
        <box size="10.0 0.18 0.4"/>
      </geometry>
      <material name="purple"/>
    </visual>
    <inertial>
      <origin rpy="0 0 0" xyz="0.0 0.0 0.0"/>
      <mass value="1"/>
      <inertia ixx="1.0" ixy="0.0" ixz="0.0" iyy="1.0" iyz="0.0" izz="1.0"/>
    </inertial>
  </link>
  <link name="belt_moving">
    <inertial>
      <origin rpy="0 0 0" xyz="0.0 0.0 0.0"/>
      <mass value="1"/>
      <inertia ixx="1.0" ixy="0.0" ixz="0.0" iyy="1.0" iyz="0.0" izz="1.0"/>
    </inertial>
    <collision>
      <origin rpy="0 0 0" xyz="0.0 0.0 0.05"/>
      <geometry>
        <box size="10.0 0.18 0.4"/>
      </geometry>
    </collision>
  </link>
  <joint name="belt_joint" type="prismatic">
    <origin rpy="0 0 0" xyz="0.0 0.0 0.0"/>
    <parent link="belt_visual"/>
    <child link="belt_moving"/>
    <axis xyz="1 0 0"/>
    <limit effort="100" lower="0.0" upper="1.0" velocity="100"/>
  </joint>
  <gazebo>
    <plugin filename="libROSConveyorBeltPlugin.so" name="belt_conveyor_plugin">
      <robot_namespace>/</robot_namespace>
      <link>belt_moving</link>
      <power>0</power>
      <max_velocity>1.0</max_velocity>
    </plugin>
    <material>Gazebo/Purple</material>
  </gazebo>
</robot>

